ERROR:__main__:Exception on /favicon.ico [GET]
Traceback (most recent call last):
  File "/usr/lib/python2.7/site-packages/flask/app.py", line 1817, in wsgi_app
    response = self.full_dispatch_request()
  File "/usr/lib/python2.7/site-packages/flask/app.py", line 1477, in full_dispatch_request
    rv = self.handle_user_exception(e)
  File "/usr/lib/python2.7/site-packages/flask/app.py", line 1370, in handle_user_exception
    return self.handle_http_exception(e)
  File "/usr/lib/python2.7/site-packages/flask/app.py", line 1330, in handle_http_exception
    return handler(e)
TypeError: page_not_found() takes no arguments (1 given)
ERROR:tornado.access:500 GET /favicon.ico (219.157.149.94) 72.69ms
ERROR:__main__:Exception on /favicon.ico [GET]
Traceback (most recent call last):
  File "/usr/lib/python2.7/site-packages/flask/app.py", line 1817, in wsgi_app
    response = self.full_dispatch_request()
  File "/usr/lib/python2.7/site-packages/flask/app.py", line 1477, in full_dispatch_request
    rv = self.handle_user_exception(e)
  File "/usr/lib/python2.7/site-packages/flask/app.py", line 1370, in handle_user_exception
    return self.handle_http_exception(e)
  File "/usr/lib/python2.7/site-packages/flask/app.py", line 1330, in handle_http_exception
    return handler(e)
TypeError: page_not_found() takes no arguments (1 given)
ERROR:tornado.access:500 GET /favicon.ico (219.157.149.94) 1.96ms
http://127.0.0.1:1234
Traceback (most recent call last):
  File "manage.py", line 56, in <module>
    IOLoop.instance().start()
  File "/usr/lib64/python2.7/site-packages/tornado/ioloop.py", line 863, in start
    event_pairs = self._impl.poll(poll_timeout)
KeyboardInterrupt
http://127.0.0.1:1234
Traceback (most recent call last):
  File "manage.py", line 56, in <module>
    IOLoop.instance().start()
  File "/usr/lib64/python2.7/site-packages/tornado/ioloop.py", line 863, in start
    event_pairs = self._impl.poll(poll_timeout)
KeyboardInterrupt
ERROR:__main__:Exception on /favicon.ico [GET]
Traceback (most recent call last):
  File "/usr/lib/python2.7/site-packages/flask/app.py", line 1817, in wsgi_app
    response = self.full_dispatch_request()
  File "/usr/lib/python2.7/site-packages/flask/app.py", line 1477, in full_dispatch_request
    rv = self.handle_user_exception(e)
  File "/usr/lib/python2.7/site-packages/flask/app.py", line 1370, in handle_user_exception
    return self.handle_http_exception(e)
  File "/usr/lib/python2.7/site-packages/flask/app.py", line 1330, in handle_http_exception
    return handler(e)
TypeError: page_not_found() takes no arguments (1 given)
ERROR:tornado.access:500 GET /favicon.ico (219.157.149.94) 5.03ms
ERROR:__main__:Exception on /favicon.ico [GET]
Traceback (most recent call last):
  File "/usr/lib/python2.7/site-packages/flask/app.py", line 1817, in wsgi_app
    response = self.full_dispatch_request()
  File "/usr/lib/python2.7/site-packages/flask/app.py", line 1477, in full_dispatch_request
    rv = self.handle_user_exception(e)
  File "/usr/lib/python2.7/site-packages/flask/app.py", line 1370, in handle_user_exception
    return self.handle_http_exception(e)
  File "/usr/lib/python2.7/site-packages/flask/app.py", line 1330, in handle_http_exception
    return handler(e)
TypeError: page_not_found() takes no arguments (1 given)
ERROR:tornado.access:500 GET /favicon.ico (219.157.149.94) 2.20ms
ERROR:__main__:Exception on /favicon.ico [GET]
Traceback (most recent call last):
  File "/usr/lib/python2.7/site-packages/flask/app.py", line 1817, in wsgi_app
    response = self.full_dispatch_request()
  File "/usr/lib/python2.7/site-packages/flask/app.py", line 1477, in full_dispatch_request
    rv = self.handle_user_exception(e)
  File "/usr/lib/python2.7/site-packages/flask/app.py", line 1370, in handle_user_exception
    return self.handle_http_exception(e)
  File "/usr/lib/python2.7/site-packages/flask/app.py", line 1330, in handle_http_exception
    return handler(e)
TypeError: page_not_found() takes no arguments (1 given)
ERROR:tornado.access:500 GET /favicon.ico (219.157.149.94) 1.86ms
ERROR:__main__:Exception on /favicon.ico [GET]
Traceback (most recent call last):
  File "/usr/lib/python2.7/site-packages/flask/app.py", line 1817, in wsgi_app
    response = self.full_dispatch_request()
  File "/usr/lib/python2.7/site-packages/flask/app.py", line 1477, in full_dispatch_request
    rv = self.handle_user_exception(e)
  File "/usr/lib/python2.7/site-packages/flask/app.py", line 1370, in handle_user_exception
    return self.handle_http_exception(e)
  File "/usr/lib/python2.7/site-packages/flask/app.py", line 1330, in handle_http_exception
    return handler(e)
TypeError: page_not_found() takes no arguments (1 given)
ERROR:tornado.access:500 GET /favicon.ico (219.157.149.94) 2.31ms
ERROR:__main__:Exception on /http://www.baidu.com/cache/global/img/gs.gif [GET]
Traceback (most recent call last):
  File "/usr/lib/python2.7/site-packages/flask/app.py", line 1817, in wsgi_app
    response = self.full_dispatch_request()
  File "/usr/lib/python2.7/site-packages/flask/app.py", line 1477, in full_dispatch_request
    rv = self.handle_user_exception(e)
  File "/usr/lib/python2.7/site-packages/flask/app.py", line 1370, in handle_user_exception
    return self.handle_http_exception(e)
  File "/usr/lib/python2.7/site-packages/flask/app.py", line 1330, in handle_http_exception
    return handler(e)
TypeError: page_not_found() takes no arguments (1 given)
ERROR:tornado.access:500 GET http://www.baidu.com/cache/global/img/gs.gif (93.174.93.136) 4.68ms
